2024-08-04 00:33:14,483:WARNING:PyNaCl is not installed, voice will NOT be supported
2024-08-04 00:33:14,487:INFO:logging in using static token
2024-08-04 00:33:15,431:INFO:Shard ID None has connected to Gateway (Session ID: 2971788e4957f6954946781d307a9377).
2024-08-04 00:33:29,736:ERROR:Ignoring exception in command None
discord.ext.commands.errors.CommandNotFound: Command "play" is not found
2024-08-04 00:34:35,206:WARNING:PyNaCl is not installed, voice will NOT be supported
2024-08-04 00:34:35,208:INFO:logging in using static token
2024-08-04 00:34:36,226:INFO:Shard ID None has connected to Gateway (Session ID: 64be362ddf4c12e6385aa51e26c01b53).
2024-08-04 00:35:21,200:WARNING:PyNaCl is not installed, voice will NOT be supported
2024-08-04 00:35:21,218:INFO:logging in using static token
2024-08-04 00:35:22,071:INFO:Shard ID None has connected to Gateway (Session ID: aab06b5d258d5bdac1ee2e50d83cecb2).
2024-08-04 00:35:28,237:ERROR:Ignoring exception in on_command_error
Traceback (most recent call last):
  File "C:\Users\jr\AppData\Local\Programs\Python\Python312\Lib\site-packages\discord\ext\commands\core.py", line 235, in wrapped
    ret = await coro(*args, **kwargs)
          ^^^^^^^^^^^^^^^^^^^^^^^^^^^
  File "C:\Users\jr\ChockeMusicBot\music.py", line 39, in play
    await channel.connect()
  File "C:\Users\jr\AppData\Local\Programs\Python\Python312\Lib\site-packages\discord\abc.py", line 1958, in connect
    voice: T = cls(client, self)
               ^^^^^^^^^^^^^^^^^
  File "C:\Users\jr\AppData\Local\Programs\Python\Python312\Lib\site-packages\discord\voice_client.py", line 220, in __init__
    raise RuntimeError("PyNaCl library needed in order to use voice")
RuntimeError: PyNaCl library needed in order to use voice

The above exception was the direct cause of the following exception:

Traceback (most recent call last):
  File "C:\Users\jr\AppData\Local\Programs\Python\Python312\Lib\site-packages\discord\client.py", line 449, in _run_event
    await coro(*args, **kwargs)
  File "C:\Users\jr\ChockeMusicBot\bot.py", line 24, in on_command_error
    raise error
  File "C:\Users\jr\AppData\Local\Programs\Python\Python312\Lib\site-packages\discord\ext\commands\bot.py", line 1366, in invoke
    await ctx.command.invoke(ctx)
  File "C:\Users\jr\AppData\Local\Programs\Python\Python312\Lib\site-packages\discord\ext\commands\core.py", line 1029, in invoke
    await injected(*ctx.args, **ctx.kwargs)  # type: ignore
    ^^^^^^^^^^^^^^^^^^^^^^^^^^^^^^^^^^^^^^^
  File "C:\Users\jr\AppData\Local\Programs\Python\Python312\Lib\site-packages\discord\ext\commands\core.py", line 244, in wrapped
    raise CommandInvokeError(exc) from exc
discord.ext.commands.errors.CommandInvokeError: Command raised an exception: RuntimeError: PyNaCl library needed in order to use voice
2024-08-04 00:39:17,943:INFO:logging in using static token
2024-08-04 00:39:18,938:INFO:Shard ID None has connected to Gateway (Session ID: 54083352d8e3c17df879178944258dd0).
2024-08-04 00:39:24,606:INFO:Connecting to voice...
2024-08-04 00:39:24,607:INFO:Starting voice handshake... (connection attempt 1)
2024-08-04 00:39:24,862:INFO:Voice handshake complete. Endpoint found: brazil11077.discord.media
2024-08-04 00:39:25,013:INFO:Voice connection complete.
2024-08-04 00:39:25,967:ERROR:Ignoring exception in on_command_error
Traceback (most recent call last):
  File "C:\Users\jr\ChockeMusicBot\venv\Lib\site-packages\youtube_dl\YoutubeDL.py", line 815, in wrapper
    return func(self, *args, **kwargs)
           ^^^^^^^^^^^^^^^^^^^^^^^^^^^
  File "C:\Users\jr\ChockeMusicBot\venv\Lib\site-packages\youtube_dl\YoutubeDL.py", line 836, in __extract_info
    ie_result = ie.extract(url)
                ^^^^^^^^^^^^^^^
  File "C:\Users\jr\ChockeMusicBot\venv\Lib\site-packages\youtube_dl\extractor\common.py", line 534, in extract
    ie_result = self._real_extract(url)
                ^^^^^^^^^^^^^^^^^^^^^^^
  File "C:\Users\jr\ChockeMusicBot\venv\Lib\site-packages\youtube_dl\extractor\youtube.py", line 1794, in _real_extract
    'uploader_id': self._search_regex(r'/(?:channel|user)/([^/?&#]+)', owner_profile_url, 'uploader id') if owner_profile_url else None,
                   ^^^^^^^^^^^^^^^^^^^^^^^^^^^^^^^^^^^^^^^^^^^^^^^^^^^^^^^^^^^^^^^^^^^^^^^^^^^^^^^^^^^^^
  File "C:\Users\jr\ChockeMusicBot\venv\Lib\site-packages\youtube_dl\extractor\common.py", line 1012, in _search_regex
    raise RegexNotFoundError('Unable to extract %s' % _name)
youtube_dl.utils.RegexNotFoundError: Unable to extract uploader id; please report this issue on https://yt-dl.org/bug . Make sure you are using the latest version; see  https://yt-dl.org/update  on how to update. Be sure to call youtube-dl with the --verbose flag and include its complete output.

During handling of the above exception, another exception occurred:

Traceback (most recent call last):
  File "C:\Users\jr\ChockeMusicBot\venv\Lib\site-packages\discord\ext\commands\core.py", line 235, in wrapped
    ret = await coro(*args, **kwargs)
          ^^^^^^^^^^^^^^^^^^^^^^^^^^^
  File "C:\Users\jr\ChockeMusicBot\music.py", line 42, in play
    await ctx.send(f"Adicionado à fila: {self.search_yt(url)['title']}")
                                         ^^^^^^^^^^^^^^^^^^^
  File "C:\Users\jr\ChockeMusicBot\music.py", line 22, in search_yt
    info = ydl.extract_info(url, download=False)
           ^^^^^^^^^^^^^^^^^^^^^^^^^^^^^^^^^^^^^
  File "C:\Users\jr\ChockeMusicBot\venv\Lib\site-packages\youtube_dl\YoutubeDL.py", line 808, in extract_info
    return self.__extract_info(url, ie, download, extra_info, process)
           ^^^^^^^^^^^^^^^^^^^^^^^^^^^^^^^^^^^^^^^^^^^^^^^^^^^^^^^^^^^
  File "C:\Users\jr\ChockeMusicBot\venv\Lib\site-packages\youtube_dl\YoutubeDL.py", line 824, in wrapper
    self.report_error(compat_str(e), e.format_traceback())
  File "C:\Users\jr\ChockeMusicBot\venv\Lib\site-packages\youtube_dl\YoutubeDL.py", line 628, in report_error
    self.trouble(error_message, tb)
  File "C:\Users\jr\ChockeMusicBot\venv\Lib\site-packages\youtube_dl\YoutubeDL.py", line 598, in trouble
    raise DownloadError(message, exc_info)
youtube_dl.utils.DownloadError: ERROR: Unable to extract uploader id; please report this issue on https://yt-dl.org/bug . Make sure you are using the latest version; see  https://yt-dl.org/update  on how to update. Be sure to call youtube-dl with the --verbose flag and include its complete output.

The above exception was the direct cause of the following exception:

Traceback (most recent call last):
  File "C:\Users\jr\ChockeMusicBot\venv\Lib\site-packages\discord\client.py", line 449, in _run_event
    await coro(*args, **kwargs)
  File "C:\Users\jr\ChockeMusicBot\bot.py", line 24, in on_command_error
    raise error
  File "C:\Users\jr\ChockeMusicBot\venv\Lib\site-packages\discord\ext\commands\bot.py", line 1366, in invoke
    await ctx.command.invoke(ctx)
  File "C:\Users\jr\ChockeMusicBot\venv\Lib\site-packages\discord\ext\commands\core.py", line 1029, in invoke
    await injected(*ctx.args, **ctx.kwargs)  # type: ignore
    ^^^^^^^^^^^^^^^^^^^^^^^^^^^^^^^^^^^^^^^
  File "C:\Users\jr\ChockeMusicBot\venv\Lib\site-packages\discord\ext\commands\core.py", line 244, in wrapped
    raise CommandInvokeError(exc) from exc
discord.ext.commands.errors.CommandInvokeError: Command raised an exception: DownloadError: ERROR: Unable to extract uploader id; please report this issue on https://yt-dl.org/bug . Make sure you are using the latest version; see  https://yt-dl.org/update  on how to update. Be sure to call youtube-dl with the --verbose flag and include its complete output.
2024-08-04 00:39:45,972:INFO:The voice handshake is being terminated for Channel ID 936833639784783942 (Guild ID 911285540400287794)
2024-08-04 00:40:21,765:INFO:logging in using static token
2024-08-04 00:40:22,700:INFO:Shard ID None has connected to Gateway (Session ID: b32ea7a81a8093489c5d0416520c5b46).
2024-08-04 00:40:27,274:INFO:Connecting to voice...
2024-08-04 00:40:27,275:INFO:Starting voice handshake... (connection attempt 1)
2024-08-04 00:40:27,902:INFO:Voice handshake complete. Endpoint found: brazil11077.discord.media
2024-08-04 00:40:28,020:INFO:Voice connection complete.
2024-08-04 00:40:51,494:INFO:ffmpeg process 23336 has not terminated. Waiting to terminate...
2024-08-04 00:40:52,293:INFO:ffmpeg process 23336 should have terminated with a return code of 1.
2024-08-04 00:42:52,632:INFO:The voice handshake is being terminated for Channel ID 936833639784783942 (Guild ID 911285540400287794)
2024-08-04 00:42:52,634:INFO:ffmpeg process 17388 has not terminated. Waiting to terminate...
2024-08-04 00:42:53,423:INFO:ffmpeg process 17388 should have terminated with a return code of 1.
2024-08-04 00:43:23,318:INFO:logging in using static token
2024-08-04 00:43:24,261:INFO:Shard ID None has connected to Gateway (Session ID: 30fd6793893fe95a87d87d3ad862f90c).
2024-08-04 00:43:29,300:INFO:Connecting to voice...
2024-08-04 00:43:29,301:INFO:Starting voice handshake... (connection attempt 1)
2024-08-04 00:43:29,558:INFO:Voice handshake complete. Endpoint found: brazil11077.discord.media
2024-08-04 00:43:29,695:INFO:Voice connection complete.
2024-08-04 00:45:29,552:INFO:The voice handshake is being terminated for Channel ID 936833639784783942 (Guild ID 911285540400287794)
2024-08-04 00:45:29,566:INFO:ffmpeg process 13760 has not terminated. Waiting to terminate...
2024-08-04 00:45:30,423:INFO:ffmpeg process 13760 should have terminated with a return code of 1.
2024-08-04 00:46:23,375:INFO:logging in using static token
2024-08-04 00:46:24,272:INFO:Shard ID None has connected to Gateway (Session ID: ecf3847dba30b436cbf4d0fc336bc697).
2024-08-04 00:46:32,305:INFO:Connecting to voice...
2024-08-04 00:46:32,306:INFO:Starting voice handshake... (connection attempt 1)
2024-08-04 00:46:32,568:INFO:Voice handshake complete. Endpoint found: brazil11077.discord.media
2024-08-04 00:46:32,685:INFO:Voice connection complete.
2024-08-04 00:46:35,825:ERROR:Ignoring exception in on_command_error
Traceback (most recent call last):
  File "C:\Users\jr\ChockeMusicBot\venv\Lib\site-packages\pytube\__main__.py", line 181, in fmt_streams
    extract.apply_signature(stream_manifest, self.vid_info, self.js)
  File "C:\Users\jr\ChockeMusicBot\venv\Lib\site-packages\pytube\extract.py", line 409, in apply_signature
    cipher = Cipher(js=js)
             ^^^^^^^^^^^^^
  File "C:\Users\jr\ChockeMusicBot\venv\Lib\site-packages\pytube\cipher.py", line 43, in __init__
    self.throttling_plan = get_throttling_plan(js)
                           ^^^^^^^^^^^^^^^^^^^^^^^
  File "C:\Users\jr\ChockeMusicBot\venv\Lib\site-packages\pytube\cipher.py", line 405, in get_throttling_plan
    raw_code = get_throttling_function_code(js)
               ^^^^^^^^^^^^^^^^^^^^^^^^^^^^^^^^
  File "C:\Users\jr\ChockeMusicBot\venv\Lib\site-packages\pytube\cipher.py", line 311, in get_throttling_function_code
    name = re.escape(get_throttling_function_name(js))
                     ^^^^^^^^^^^^^^^^^^^^^^^^^^^^^^^^
  File "C:\Users\jr\ChockeMusicBot\venv\Lib\site-packages\pytube\cipher.py", line 296, in get_throttling_function_name
    raise RegexMatchError(
pytube.exceptions.RegexMatchError: get_throttling_function_name: could not find match for multiple

During handling of the above exception, another exception occurred:

Traceback (most recent call last):
  File "C:\Users\jr\ChockeMusicBot\venv\Lib\site-packages\discord\ext\commands\core.py", line 235, in wrapped
    ret = await coro(*args, **kwargs)
          ^^^^^^^^^^^^^^^^^^^^^^^^^^^
  File "C:\Users\jr\ChockeMusicBot\music.py", line 47, in play
    await self.play_next(ctx)
  File "C:\Users\jr\ChockeMusicBot\music.py", line 32, in play_next
    audio_file, title = await asyncio.to_thread(self.download_audio, m_url)
                        ^^^^^^^^^^^^^^^^^^^^^^^^^^^^^^^^^^^^^^^^^^^^^^^^^^^
  File "C:\Users\jr\AppData\Local\Programs\Python\Python312\Lib\asyncio\threads.py", line 25, in to_thread
    return await loop.run_in_executor(None, func_call)
           ^^^^^^^^^^^^^^^^^^^^^^^^^^^^^^^^^^^^^^^^^^^
  File "C:\Users\jr\AppData\Local\Programs\Python\Python312\Lib\concurrent\futures\thread.py", line 58, in run
    result = self.fn(*self.args, **self.kwargs)
             ^^^^^^^^^^^^^^^^^^^^^^^^^^^^^^^^^^
  File "C:\Users\jr\ChockeMusicBot\music.py", line 18, in download_audio
    stream = yt.streams.filter(only_audio=True).first()
             ^^^^^^^^^^
  File "C:\Users\jr\ChockeMusicBot\venv\Lib\site-packages\pytube\__main__.py", line 296, in streams
    return StreamQuery(self.fmt_streams)
                       ^^^^^^^^^^^^^^^^
  File "C:\Users\jr\ChockeMusicBot\venv\Lib\site-packages\pytube\__main__.py", line 188, in fmt_streams
    extract.apply_signature(stream_manifest, self.vid_info, self.js)
  File "C:\Users\jr\ChockeMusicBot\venv\Lib\site-packages\pytube\extract.py", line 409, in apply_signature
    cipher = Cipher(js=js)
             ^^^^^^^^^^^^^
  File "C:\Users\jr\ChockeMusicBot\venv\Lib\site-packages\pytube\cipher.py", line 43, in __init__
    self.throttling_plan = get_throttling_plan(js)
                           ^^^^^^^^^^^^^^^^^^^^^^^
  File "C:\Users\jr\ChockeMusicBot\venv\Lib\site-packages\pytube\cipher.py", line 405, in get_throttling_plan
    raw_code = get_throttling_function_code(js)
               ^^^^^^^^^^^^^^^^^^^^^^^^^^^^^^^^
  File "C:\Users\jr\ChockeMusicBot\venv\Lib\site-packages\pytube\cipher.py", line 311, in get_throttling_function_code
    name = re.escape(get_throttling_function_name(js))
                     ^^^^^^^^^^^^^^^^^^^^^^^^^^^^^^^^
  File "C:\Users\jr\ChockeMusicBot\venv\Lib\site-packages\pytube\cipher.py", line 296, in get_throttling_function_name
    raise RegexMatchError(
pytube.exceptions.RegexMatchError: get_throttling_function_name: could not find match for multiple

The above exception was the direct cause of the following exception:

Traceback (most recent call last):
  File "C:\Users\jr\ChockeMusicBot\venv\Lib\site-packages\discord\client.py", line 449, in _run_event
    await coro(*args, **kwargs)
  File "C:\Users\jr\ChockeMusicBot\bot.py", line 24, in on_command_error
    raise error
  File "C:\Users\jr\ChockeMusicBot\venv\Lib\site-packages\discord\ext\commands\bot.py", line 1366, in invoke
    await ctx.command.invoke(ctx)
  File "C:\Users\jr\ChockeMusicBot\venv\Lib\site-packages\discord\ext\commands\core.py", line 1029, in invoke
    await injected(*ctx.args, **ctx.kwargs)  # type: ignore
    ^^^^^^^^^^^^^^^^^^^^^^^^^^^^^^^^^^^^^^^
  File "C:\Users\jr\ChockeMusicBot\venv\Lib\site-packages\discord\ext\commands\core.py", line 244, in wrapped
    raise CommandInvokeError(exc) from exc
discord.ext.commands.errors.CommandInvokeError: Command raised an exception: RegexMatchError: get_throttling_function_name: could not find match for multiple
2024-08-04 00:47:26,261:INFO:The voice handshake is being terminated for Channel ID 936833639784783942 (Guild ID 911285540400287794)
2024-08-04 00:48:21,660:INFO:logging in using static token
2024-08-04 00:48:22,518:INFO:Shard ID None has connected to Gateway (Session ID: 1012ff13319ab2332487fcfb6ebef38a).
2024-08-04 00:48:28,051:INFO:Connecting to voice...
2024-08-04 00:48:28,052:INFO:Starting voice handshake... (connection attempt 1)
2024-08-04 00:48:28,318:INFO:Voice handshake complete. Endpoint found: brazil11077.discord.media
2024-08-04 00:48:28,435:INFO:Voice connection complete.
2024-08-04 00:48:36,442:INFO:ffmpeg process 21072 successfully terminated with return code of 4294967294.
2024-08-04 00:48:37,362:INFO:The voice handshake is being terminated for Channel ID 936833639784783942 (Guild ID 911285540400287794)
2024-08-04 00:48:40,585:INFO:Connecting to voice...
2024-08-04 00:48:40,585:INFO:Starting voice handshake... (connection attempt 1)
2024-08-04 00:48:40,834:INFO:Voice handshake complete. Endpoint found: brazil11077.discord.media
2024-08-04 00:48:40,979:INFO:Voice connection complete.
2024-08-04 00:48:48,587:INFO:ffmpeg process 18304 successfully terminated with return code of 4294967294.
2024-08-04 00:48:50,949:INFO:The voice handshake is being terminated for Channel ID 936833639784783942 (Guild ID 911285540400287794)
2024-08-04 00:49:51,375:INFO:logging in using static token
2024-08-04 00:49:52,338:INFO:Shard ID None has connected to Gateway (Session ID: 1726d25fa1e572cdb89da55977a18427).
2024-08-04 00:49:57,794:INFO:Connecting to voice...
2024-08-04 00:49:57,795:INFO:Starting voice handshake... (connection attempt 1)
2024-08-04 00:49:58,042:INFO:Voice handshake complete. Endpoint found: brazil11077.discord.media
2024-08-04 00:49:58,156:INFO:Voice connection complete.
2024-08-04 00:50:06,457:INFO:The voice handshake is being terminated for Channel ID 936833639784783942 (Guild ID 911285540400287794)
